{"uuid": "89d44065-8051-4bbc-888e-093d2cdae63c", "children": ["8d62f448-2c5b-41b5-9990-d055494b08e3"], "befores": [{"name": "browser", "status": "broken", "statusDetails": {"message": "urllib3.exceptions.MaxRetryError: HTTPConnectionPool(host='127.0.0.1', port=54848): Max retries exceeded with url: /session/36435e82bb7378286bf5dfb1e270447b/window/maximize (Caused by NewConnectionError('<urllib3.connection.HTTPConnection object at 0x0000015A513B79C8>: Failed to establish a new connection: [WinError 10061] 由于目标计算机积极拒绝，无法连接。'))\n", "trace": "  File \"D:\\python\\lib\\site-packages\\pluggy\\callers.py\", line 187, in _multicall\n    res = hook_impl.function(*args)\n  File \"D:\\python\\lib\\site-packages\\_pytest\\fixtures.py\", line 1111, in pytest_fixture_setup\n    result = call_fixture_func(fixturefunc, request, kwargs)\n  File \"D:\\python\\lib\\site-packages\\_pytest\\fixtures.py\", line 908, in call_fixture_func\n    fixture_result = next(generator)\n  File \"F:\\pytestUI\\case\\conftest.py\", line 91, in browser\n    _driver =Base().chromeDriver\n  File \"F:\\pytestUI\\common\\base.py\", line 37, in __init__\n    self.driver.maximize_window()\n  File \"D:\\python\\lib\\site-packages\\selenium\\webdriver\\remote\\webdriver.py\", line 737, in maximize_window\n    self.execute(command, params)\n  File \"D:\\python\\lib\\site-packages\\selenium\\webdriver\\remote\\webdriver.py\", line 319, in execute\n    response = self.command_executor.execute(driver_command, params)\n  File \"D:\\python\\lib\\site-packages\\selenium\\webdriver\\remote\\remote_connection.py\", line 374, in execute\n    return self._request(command_info[0], url, body=data)\n  File \"D:\\python\\lib\\site-packages\\selenium\\webdriver\\remote\\remote_connection.py\", line 397, in _request\n    resp = self._conn.request(method, url, body=body, headers=headers)\n  File \"D:\\python\\lib\\site-packages\\urllib3\\request.py\", line 70, in request\n    **urlopen_kw)\n  File \"D:\\python\\lib\\site-packages\\urllib3\\request.py\", line 148, in request_encode_body\n    return self.urlopen(method, url, **extra_kw)\n  File \"D:\\python\\lib\\site-packages\\urllib3\\poolmanager.py\", line 321, in urlopen\n    response = conn.urlopen(method, u.request_uri, **kw)\n  File \"D:\\python\\lib\\site-packages\\urllib3\\connectionpool.py\", line 668, in urlopen\n    **response_kw)\n  File \"D:\\python\\lib\\site-packages\\urllib3\\connectionpool.py\", line 668, in urlopen\n    **response_kw)\n  File \"D:\\python\\lib\\site-packages\\urllib3\\connectionpool.py\", line 668, in urlopen\n    **response_kw)\n  File \"D:\\python\\lib\\site-packages\\urllib3\\connectionpool.py\", line 639, in urlopen\n    _stacktrace=sys.exc_info()[2])\n  File \"D:\\python\\lib\\site-packages\\urllib3\\util\\retry.py\", line 388, in increment\n    raise MaxRetryError(_pool, url, error or ResponseError(cause))\n"}, "start": 1607929283775, "stop": 1607929287782}], "start": 1607929283775, "stop": 1607929287906}